Watching for file changes with StatReloader
Exception in thread django-main-thread:
Traceback (most recent call last):
  File "/usr/lib/python3.12/threading.py", line 1073, in _bootstrap_inner
    self.run()
  File "/usr/lib/python3.12/threading.py", line 1010, in run
    self._target(*self._args, **self._kwargs)
  File "/root/applegenie/venv/lib/python3.12/site-packages/django/utils/autoreload.py", line 64, in wrapper
    fn(*args, **kwargs)
  File "/root/applegenie/venv/lib/python3.12/site-packages/django/core/management/commands/runserver.py", line 125, in inner_run
    autoreload.raise_last_exception()
  File "/root/applegenie/venv/lib/python3.12/site-packages/django/utils/autoreload.py", line 87, in raise_last_exception
    raise _exception[1]
  File "/root/applegenie/venv/lib/python3.12/site-packages/django/core/management/__init__.py", line 394, in execute
    autoreload.check_errors(django.setup)()
  File "/root/applegenie/venv/lib/python3.12/site-packages/django/utils/autoreload.py", line 64, in wrapper
    fn(*args, **kwargs)
  File "/root/applegenie/venv/lib/python3.12/site-packages/django/__init__.py", line 24, in setup
    apps.populate(settings.INSTALLED_APPS)
  File "/root/applegenie/venv/lib/python3.12/site-packages/django/apps/registry.py", line 91, in populate
    app_config = AppConfig.create(entry)
                 ^^^^^^^^^^^^^^^^^^^^^^^
  File "/root/applegenie/venv/lib/python3.12/site-packages/django/apps/config.py", line 193, in create
    import_module(entry)
  File "/usr/lib/python3.12/importlib/__init__.py", line 90, in import_module
    return _bootstrap._gcd_import(name[level:], package, level)
           ^^^^^^^^^^^^^^^^^^^^^^^^^^^^^^^^^^^^^^^^^^^^^^^^^^^^
  File "<frozen importlib._bootstrap>", line 1387, in _gcd_import
  File "<frozen importlib._bootstrap>", line 1360, in _find_and_load
  File "<frozen importlib._bootstrap>", line 1331, in _find_and_load_unlocked
  File "<frozen importlib._bootstrap>", line 935, in _load_unlocked
  File "<frozen importlib._bootstrap_external>", line 995, in exec_module
  File "<frozen importlib._bootstrap>", line 488, in _call_with_frames_removed
  File "/root/applegenie/venv/lib/python3.12/site-packages/drf_yasg/__init__.py", line 2, in <module>
    from pkg_resources import DistributionNotFound, get_distribution
ModuleNotFoundError: No module named 'pkg_resources'
Watching for file changes with StatReloader
Exception in thread django-main-thread:
Traceback (most recent call last):
  File "/usr/lib/python3.12/threading.py", line 1073, in _bootstrap_inner
    self.run()
  File "/usr/lib/python3.12/threading.py", line 1010, in run
    self._target(*self._args, **self._kwargs)
  File "/root/applegenie/venv/lib/python3.12/site-packages/django/utils/autoreload.py", line 64, in wrapper
    fn(*args, **kwargs)
  File "/root/applegenie/venv/lib/python3.12/site-packages/django/core/management/commands/runserver.py", line 125, in inner_run
    autoreload.raise_last_exception()
  File "/root/applegenie/venv/lib/python3.12/site-packages/django/utils/autoreload.py", line 87, in raise_last_exception
    raise _exception[1]
  File "/root/applegenie/venv/lib/python3.12/site-packages/django/core/management/__init__.py", line 394, in execute
    autoreload.check_errors(django.setup)()
  File "/root/applegenie/venv/lib/python3.12/site-packages/django/utils/autoreload.py", line 64, in wrapper
    fn(*args, **kwargs)
  File "/root/applegenie/venv/lib/python3.12/site-packages/django/__init__.py", line 24, in setup
    apps.populate(settings.INSTALLED_APPS)
  File "/root/applegenie/venv/lib/python3.12/site-packages/django/apps/registry.py", line 116, in populate
    app_config.import_models()
  File "/root/applegenie/venv/lib/python3.12/site-packages/django/apps/config.py", line 269, in import_models
    self.models_module = import_module(models_module_name)
                         ^^^^^^^^^^^^^^^^^^^^^^^^^^^^^^^^^
  File "/usr/lib/python3.12/importlib/__init__.py", line 90, in import_module
    return _bootstrap._gcd_import(name[level:], package, level)
           ^^^^^^^^^^^^^^^^^^^^^^^^^^^^^^^^^^^^^^^^^^^^^^^^^^^^
  File "<frozen importlib._bootstrap>", line 1387, in _gcd_import
  File "<frozen importlib._bootstrap>", line 1360, in _find_and_load
  File "<frozen importlib._bootstrap>", line 1331, in _find_and_load_unlocked
  File "<frozen importlib._bootstrap>", line 935, in _load_unlocked
  File "<frozen importlib._bootstrap_external>", line 995, in exec_module
  File "<frozen importlib._bootstrap>", line 488, in _call_with_frames_removed
  File "/root/applegenie/core_app_root/apple_gifting/models.py", line 4, in <module>
    class AppleGiftingModel(models.Model):
  File "/root/applegenie/core_app_root/apple_gifting/models.py", line 5, in AppleGiftingModel
    number_of_apples=models.IntegerField(db_default=0,null=True)
                     ^^^^^^^^^^^^^^^^^^^^^^^^^^^^^^^^^^^^^^^^^^^
TypeError: Field.__init__() got an unexpected keyword argument 'db_default'
/root/applegenie/core_app_root/apple_gifting/models.py changed, reloading.
Watching for file changes with StatReloader
Exception in thread django-main-thread:
Traceback (most recent call last):
  File "/usr/lib/python3.12/threading.py", line 1073, in _bootstrap_inner
    self.run()
  File "/usr/lib/python3.12/threading.py", line 1010, in run
    self._target(*self._args, **self._kwargs)
  File "/root/applegenie/venv/lib/python3.12/site-packages/django/utils/autoreload.py", line 64, in wrapper
    fn(*args, **kwargs)
  File "/root/applegenie/venv/lib/python3.12/site-packages/django/core/management/commands/runserver.py", line 133, in inner_run
    self.check(display_num_errors=True)
  File "/root/applegenie/venv/lib/python3.12/site-packages/django/core/management/base.py", line 556, in check
    raise SystemCheckError(msg)
django.core.management.base.SystemCheckError: SystemCheckError: System check identified some issues:

ERRORS:
core_app_root_human_attributes.HumanQualities.hobbies: (fields.E005) 'choices' must be an iterable containing (actual value, human readable name) tuples.
core_app_root_human_attributes.HumanQualities.shirt_size: (fields.E005) 'choices' must be an iterable containing (actual value, human readable name) tuples.
core_app_root_human_attributes.HumanQualities.skin_color: (fields.E005) 'choices' must be an iterable containing (actual value, human readable name) tuples.

System check identified 3 issues (0 silenced).
/root/applegenie/core_app_root/human_attributes/models.py changed, reloading.
Performing system checks...

Watching for file changes with StatReloader
Exception in thread django-main-thread:
Traceback (most recent call last):
  File "/usr/lib/python3.12/threading.py", line 1073, in _bootstrap_inner
    self.run()
  File "/usr/lib/python3.12/threading.py", line 1010, in run
    self._target(*self._args, **self._kwargs)
  File "/root/applegenie/venv/lib/python3.12/site-packages/django/utils/autoreload.py", line 64, in wrapper
    fn(*args, **kwargs)
  File "/root/applegenie/venv/lib/python3.12/site-packages/django/core/management/commands/runserver.py", line 125, in inner_run
    autoreload.raise_last_exception()
  File "/root/applegenie/venv/lib/python3.12/site-packages/django/utils/autoreload.py", line 87, in raise_last_exception
    raise _exception[1]
  File "/root/applegenie/venv/lib/python3.12/site-packages/django/core/management/__init__.py", line 394, in execute
    autoreload.check_errors(django.setup)()
  File "/root/applegenie/venv/lib/python3.12/site-packages/django/utils/autoreload.py", line 64, in wrapper
    fn(*args, **kwargs)
  File "/root/applegenie/venv/lib/python3.12/site-packages/django/__init__.py", line 24, in setup
    apps.populate(settings.INSTALLED_APPS)
  File "/root/applegenie/venv/lib/python3.12/site-packages/django/apps/registry.py", line 116, in populate
    app_config.import_models()
  File "/root/applegenie/venv/lib/python3.12/site-packages/django/apps/config.py", line 269, in import_models
    self.models_module = import_module(models_module_name)
                         ^^^^^^^^^^^^^^^^^^^^^^^^^^^^^^^^^
  File "/usr/lib/python3.12/importlib/__init__.py", line 90, in import_module
    return _bootstrap._gcd_import(name[level:], package, level)
           ^^^^^^^^^^^^^^^^^^^^^^^^^^^^^^^^^^^^^^^^^^^^^^^^^^^^
  File "<frozen importlib._bootstrap>", line 1387, in _gcd_import
  File "<frozen importlib._bootstrap>", line 1360, in _find_and_load
  File "<frozen importlib._bootstrap>", line 1331, in _find_and_load_unlocked
  File "<frozen importlib._bootstrap>", line 935, in _load_unlocked
  File "<frozen importlib._bootstrap_external>", line 991, in exec_module
  File "<frozen importlib._bootstrap_external>", line 1129, in get_code
  File "<frozen importlib._bootstrap_external>", line 1059, in source_to_code
  File "<frozen importlib._bootstrap>", line 488, in _call_with_frames_removed
  File "/root/applegenie/core_app_root/human_attributes/models.py", line 13
    list_of_hobbies=(())"SING":"Singing","DANCE":"DANCING","COOK":"COOKING"}
                                                                           ^
SyntaxError: unmatched '}'
/root/applegenie/core_app_root/human_attributes/models.py changed, reloading.
Watching for file changes with StatReloader
Exception in thread django-main-thread:
Traceback (most recent call last):
  File "/usr/lib/python3.12/threading.py", line 1073, in _bootstrap_inner
    self.run()
  File "/usr/lib/python3.12/threading.py", line 1010, in run
    self._target(*self._args, **self._kwargs)
  File "/root/applegenie/venv/lib/python3.12/site-packages/django/utils/autoreload.py", line 64, in wrapper
    fn(*args, **kwargs)
  File "/root/applegenie/venv/lib/python3.12/site-packages/django/core/management/commands/runserver.py", line 125, in inner_run
    autoreload.raise_last_exception()
  File "/root/applegenie/venv/lib/python3.12/site-packages/django/utils/autoreload.py", line 87, in raise_last_exception
    raise _exception[1]
  File "/root/applegenie/venv/lib/python3.12/site-packages/django/core/management/__init__.py", line 394, in execute
    autoreload.check_errors(django.setup)()
  File "/root/applegenie/venv/lib/python3.12/site-packages/django/utils/autoreload.py", line 64, in wrapper
    fn(*args, **kwargs)
  File "/root/applegenie/venv/lib/python3.12/site-packages/django/__init__.py", line 24, in setup
    apps.populate(settings.INSTALLED_APPS)
  File "/root/applegenie/venv/lib/python3.12/site-packages/django/apps/registry.py", line 116, in populate
    app_config.import_models()
  File "/root/applegenie/venv/lib/python3.12/site-packages/django/apps/config.py", line 269, in import_models
    self.models_module = import_module(models_module_name)
                         ^^^^^^^^^^^^^^^^^^^^^^^^^^^^^^^^^
  File "/usr/lib/python3.12/importlib/__init__.py", line 90, in import_module
    return _bootstrap._gcd_import(name[level:], package, level)
           ^^^^^^^^^^^^^^^^^^^^^^^^^^^^^^^^^^^^^^^^^^^^^^^^^^^^
  File "<frozen importlib._bootstrap>", line 1387, in _gcd_import
  File "<frozen importlib._bootstrap>", line 1360, in _find_and_load
  File "<frozen importlib._bootstrap>", line 1331, in _find_and_load_unlocked
  File "<frozen importlib._bootstrap>", line 935, in _load_unlocked
  File "<frozen importlib._bootstrap_external>", line 991, in exec_module
  File "<frozen importlib._bootstrap_external>", line 1129, in get_code
  File "<frozen importlib._bootstrap_external>", line 1059, in source_to_code
  File "<frozen importlib._bootstrap>", line 488, in _call_with_frames_removed
  File "/root/applegenie/core_app_root/human_attributes/models.py", line 13
    list_of_hobbies=(("SING":"Singing","DANCE":"DANCING","COOK":"COOKING"}
                                                                         ^
SyntaxError: closing parenthesis '}' does not match opening parenthesis '('
/root/applegenie/core_app_root/human_attributes/models.py changed, reloading.
Watching for file changes with StatReloader
Exception in thread django-main-thread:
Traceback (most recent call last):
  File "/usr/lib/python3.12/threading.py", line 1073, in _bootstrap_inner
    self.run()
  File "/usr/lib/python3.12/threading.py", line 1010, in run
    self._target(*self._args, **self._kwargs)
  File "/root/applegenie/venv/lib/python3.12/site-packages/django/utils/autoreload.py", line 64, in wrapper
    fn(*args, **kwargs)
  File "/root/applegenie/venv/lib/python3.12/site-packages/django/core/management/commands/runserver.py", line 125, in inner_run
    autoreload.raise_last_exception()
  File "/root/applegenie/venv/lib/python3.12/site-packages/django/utils/autoreload.py", line 87, in raise_last_exception
    raise _exception[1]
  File "/root/applegenie/venv/lib/python3.12/site-packages/django/core/management/__init__.py", line 394, in execute
    autoreload.check_errors(django.setup)()
  File "/root/applegenie/venv/lib/python3.12/site-packages/django/utils/autoreload.py", line 64, in wrapper
    fn(*args, **kwargs)
  File "/root/applegenie/venv/lib/python3.12/site-packages/django/__init__.py", line 24, in setup
    apps.populate(settings.INSTALLED_APPS)
  File "/root/applegenie/venv/lib/python3.12/site-packages/django/apps/registry.py", line 116, in populate
    app_config.import_models()
  File "/root/applegenie/venv/lib/python3.12/site-packages/django/apps/config.py", line 269, in import_models
    self.models_module = import_module(models_module_name)
                         ^^^^^^^^^^^^^^^^^^^^^^^^^^^^^^^^^
  File "/usr/lib/python3.12/importlib/__init__.py", line 90, in import_module
    return _bootstrap._gcd_import(name[level:], package, level)
           ^^^^^^^^^^^^^^^^^^^^^^^^^^^^^^^^^^^^^^^^^^^^^^^^^^^^
  File "<frozen importlib._bootstrap>", line 1387, in _gcd_import
  File "<frozen importlib._bootstrap>", line 1360, in _find_and_load
  File "<frozen importlib._bootstrap>", line 1331, in _find_and_load_unlocked
  File "<frozen importlib._bootstrap>", line 935, in _load_unlocked
  File "<frozen importlib._bootstrap_external>", line 991, in exec_module
  File "<frozen importlib._bootstrap_external>", line 1129, in get_code
  File "<frozen importlib._bootstrap_external>", line 1059, in source_to_code
  File "<frozen importlib._bootstrap>", line 488, in _call_with_frames_removed
  File "/root/applegenie/core_app_root/human_attributes/models.py", line 13
    list_of_hobbies=(("SING":"Singing","DANCE":"DANCING","COOK":"COOKING"))
                            ^
SyntaxError: invalid syntax
/root/applegenie/core_app_root/human_attributes/models.py changed, reloading.
Watching for file changes with StatReloader
Exception in thread django-main-thread:
Traceback (most recent call last):
  File "/usr/lib/python3.12/threading.py", line 1073, in _bootstrap_inner
    self.run()
  File "/usr/lib/python3.12/threading.py", line 1010, in run
    self._target(*self._args, **self._kwargs)
  File "/root/applegenie/venv/lib/python3.12/site-packages/django/utils/autoreload.py", line 64, in wrapper
    fn(*args, **kwargs)
  File "/root/applegenie/venv/lib/python3.12/site-packages/django/core/management/commands/runserver.py", line 125, in inner_run
    autoreload.raise_last_exception()
  File "/root/applegenie/venv/lib/python3.12/site-packages/django/utils/autoreload.py", line 87, in raise_last_exception
    raise _exception[1]
  File "/root/applegenie/venv/lib/python3.12/site-packages/django/core/management/__init__.py", line 394, in execute
    autoreload.check_errors(django.setup)()
  File "/root/applegenie/venv/lib/python3.12/site-packages/django/utils/autoreload.py", line 64, in wrapper
    fn(*args, **kwargs)
  File "/root/applegenie/venv/lib/python3.12/site-packages/django/__init__.py", line 24, in setup
    apps.populate(settings.INSTALLED_APPS)
  File "/root/applegenie/venv/lib/python3.12/site-packages/django/apps/registry.py", line 116, in populate
    app_config.import_models()
  File "/root/applegenie/venv/lib/python3.12/site-packages/django/apps/config.py", line 269, in import_models
    self.models_module = import_module(models_module_name)
                         ^^^^^^^^^^^^^^^^^^^^^^^^^^^^^^^^^
  File "/usr/lib/python3.12/importlib/__init__.py", line 90, in import_module
    return _bootstrap._gcd_import(name[level:], package, level)
           ^^^^^^^^^^^^^^^^^^^^^^^^^^^^^^^^^^^^^^^^^^^^^^^^^^^^
  File "<frozen importlib._bootstrap>", line 1387, in _gcd_import
  File "<frozen importlib._bootstrap>", line 1360, in _find_and_load
  File "<frozen importlib._bootstrap>", line 1331, in _find_and_load_unlocked
  File "<frozen importlib._bootstrap>", line 935, in _load_unlocked
  File "<frozen importlib._bootstrap_external>", line 991, in exec_module
  File "<frozen importlib._bootstrap_external>", line 1129, in get_code
  File "<frozen importlib._bootstrap_external>", line 1059, in source_to_code
  File "<frozen importlib._bootstrap>", line 488, in _call_with_frames_removed
  File "/root/applegenie/core_app_root/human_attributes/models.py", line 8
    "S": "Small",
IndentationError: unexpected indent
/root/applegenie/core_app_root/human_attributes/models.py changed, reloading.
Watching for file changes with StatReloader
Exception in thread django-main-thread:
Traceback (most recent call last):
  File "/usr/lib/python3.12/threading.py", line 1073, in _bootstrap_inner
    self.run()
  File "/usr/lib/python3.12/threading.py", line 1010, in run
    self._target(*self._args, **self._kwargs)
  File "/root/applegenie/venv/lib/python3.12/site-packages/django/utils/autoreload.py", line 64, in wrapper
    fn(*args, **kwargs)
  File "/root/applegenie/venv/lib/python3.12/site-packages/django/core/management/commands/runserver.py", line 125, in inner_run
    autoreload.raise_last_exception()
  File "/root/applegenie/venv/lib/python3.12/site-packages/django/utils/autoreload.py", line 87, in raise_last_exception
    raise _exception[1]
  File "/root/applegenie/venv/lib/python3.12/site-packages/django/core/management/__init__.py", line 394, in execute
    autoreload.check_errors(django.setup)()
  File "/root/applegenie/venv/lib/python3.12/site-packages/django/utils/autoreload.py", line 64, in wrapper
    fn(*args, **kwargs)
  File "/root/applegenie/venv/lib/python3.12/site-packages/django/__init__.py", line 24, in setup
    apps.populate(settings.INSTALLED_APPS)
  File "/root/applegenie/venv/lib/python3.12/site-packages/django/apps/registry.py", line 116, in populate
    app_config.import_models()
  File "/root/applegenie/venv/lib/python3.12/site-packages/django/apps/config.py", line 269, in import_models
    self.models_module = import_module(models_module_name)
                         ^^^^^^^^^^^^^^^^^^^^^^^^^^^^^^^^^
  File "/usr/lib/python3.12/importlib/__init__.py", line 90, in import_module
    return _bootstrap._gcd_import(name[level:], package, level)
           ^^^^^^^^^^^^^^^^^^^^^^^^^^^^^^^^^^^^^^^^^^^^^^^^^^^^
  File "<frozen importlib._bootstrap>", line 1387, in _gcd_import
  File "<frozen importlib._bootstrap>", line 1360, in _find_and_load
  File "<frozen importlib._bootstrap>", line 1331, in _find_and_load_unlocked
  File "<frozen importlib._bootstrap>", line 935, in _load_unlocked
  File "<frozen importlib._bootstrap_external>", line 991, in exec_module
  File "<frozen importlib._bootstrap_external>", line 1129, in get_code
  File "<frozen importlib._bootstrap_external>", line 1059, in source_to_code
  File "<frozen importlib._bootstrap>", line 488, in _call_with_frames_removed
  File "/root/applegenie/core_app_root/human_attributes/models.py", line 11
    }
    ^
SyntaxError: closing parenthesis '}' does not match opening parenthesis '(' on line 7
/root/applegenie/core_app_root/human_attributes/models.py changed, reloading.
Watching for file changes with StatReloader
Exception in thread django-main-thread:
Traceback (most recent call last):
  File "/usr/lib/python3.12/threading.py", line 1073, in _bootstrap_inner
    self.run()
  File "/usr/lib/python3.12/threading.py", line 1010, in run
    self._target(*self._args, **self._kwargs)
  File "/root/applegenie/venv/lib/python3.12/site-packages/django/utils/autoreload.py", line 64, in wrapper
    fn(*args, **kwargs)
  File "/root/applegenie/venv/lib/python3.12/site-packages/django/core/management/commands/runserver.py", line 125, in inner_run
    autoreload.raise_last_exception()
  File "/root/applegenie/venv/lib/python3.12/site-packages/django/utils/autoreload.py", line 87, in raise_last_exception
    raise _exception[1]
  File "/root/applegenie/venv/lib/python3.12/site-packages/django/core/management/__init__.py", line 394, in execute
    autoreload.check_errors(django.setup)()
  File "/root/applegenie/venv/lib/python3.12/site-packages/django/utils/autoreload.py", line 64, in wrapper
    fn(*args, **kwargs)
  File "/root/applegenie/venv/lib/python3.12/site-packages/django/__init__.py", line 24, in setup
    apps.populate(settings.INSTALLED_APPS)
  File "/root/applegenie/venv/lib/python3.12/site-packages/django/apps/registry.py", line 116, in populate
    app_config.import_models()
  File "/root/applegenie/venv/lib/python3.12/site-packages/django/apps/config.py", line 269, in import_models
    self.models_module = import_module(models_module_name)
                         ^^^^^^^^^^^^^^^^^^^^^^^^^^^^^^^^^
  File "/usr/lib/python3.12/importlib/__init__.py", line 90, in import_module
    return _bootstrap._gcd_import(name[level:], package, level)
           ^^^^^^^^^^^^^^^^^^^^^^^^^^^^^^^^^^^^^^^^^^^^^^^^^^^^
  File "<frozen importlib._bootstrap>", line 1387, in _gcd_import
  File "<frozen importlib._bootstrap>", line 1360, in _find_and_load
  File "<frozen importlib._bootstrap>", line 1331, in _find_and_load_unlocked
  File "<frozen importlib._bootstrap>", line 935, in _load_unlocked
  File "<frozen importlib._bootstrap_external>", line 991, in exec_module
  File "<frozen importlib._bootstrap_external>", line 1129, in get_code
  File "<frozen importlib._bootstrap_external>", line 1059, in source_to_code
  File "<frozen importlib._bootstrap>", line 488, in _call_with_frames_removed
  File "/root/applegenie/core_app_root/human_attributes/models.py", line 7
    body_size = ((
                 ^
SyntaxError: '(' was never closed
/root/applegenie/core_app_root/human_attributes/models.py changed, reloading.
Watching for file changes with StatReloader
Exception in thread django-main-thread:
Traceback (most recent call last):
  File "/usr/lib/python3.12/threading.py", line 1073, in _bootstrap_inner
    self.run()
  File "/usr/lib/python3.12/threading.py", line 1010, in run
    self._target(*self._args, **self._kwargs)
  File "/root/applegenie/venv/lib/python3.12/site-packages/django/utils/autoreload.py", line 64, in wrapper
    fn(*args, **kwargs)
  File "/root/applegenie/venv/lib/python3.12/site-packages/django/core/management/commands/runserver.py", line 125, in inner_run
    autoreload.raise_last_exception()
  File "/root/applegenie/venv/lib/python3.12/site-packages/django/utils/autoreload.py", line 87, in raise_last_exception
    raise _exception[1]
  File "/root/applegenie/venv/lib/python3.12/site-packages/django/core/management/__init__.py", line 394, in execute
    autoreload.check_errors(django.setup)()
  File "/root/applegenie/venv/lib/python3.12/site-packages/django/utils/autoreload.py", line 64, in wrapper
    fn(*args, **kwargs)
  File "/root/applegenie/venv/lib/python3.12/site-packages/django/__init__.py", line 24, in setup
    apps.populate(settings.INSTALLED_APPS)
  File "/root/applegenie/venv/lib/python3.12/site-packages/django/apps/registry.py", line 116, in populate
    app_config.import_models()
  File "/root/applegenie/venv/lib/python3.12/site-packages/django/apps/config.py", line 269, in import_models
    self.models_module = import_module(models_module_name)
                         ^^^^^^^^^^^^^^^^^^^^^^^^^^^^^^^^^
  File "/usr/lib/python3.12/importlib/__init__.py", line 90, in import_module
    return _bootstrap._gcd_import(name[level:], package, level)
           ^^^^^^^^^^^^^^^^^^^^^^^^^^^^^^^^^^^^^^^^^^^^^^^^^^^^
  File "<frozen importlib._bootstrap>", line 1387, in _gcd_import
  File "<frozen importlib._bootstrap>", line 1360, in _find_and_load
  File "<frozen importlib._bootstrap>", line 1331, in _find_and_load_unlocked
  File "<frozen importlib._bootstrap>", line 935, in _load_unlocked
  File "<frozen importlib._bootstrap_external>", line 991, in exec_module
  File "<frozen importlib._bootstrap_external>", line 1129, in get_code
  File "<frozen importlib._bootstrap_external>", line 1059, in source_to_code
  File "<frozen importlib._bootstrap>", line 488, in _call_with_frames_removed
  File "/root/applegenie/core_app_root/human_attributes/models.py", line 7
    body_size = ((
                 ^
SyntaxError: '(' was never closed
/root/applegenie/core_app_root/human_attributes/models.py changed, reloading.
Watching for file changes with StatReloader
Exception in thread django-main-thread:
Traceback (most recent call last):
  File "/usr/lib/python3.12/threading.py", line 1073, in _bootstrap_inner
    self.run()
  File "/usr/lib/python3.12/threading.py", line 1010, in run
    self._target(*self._args, **self._kwargs)
  File "/root/applegenie/venv/lib/python3.12/site-packages/django/utils/autoreload.py", line 64, in wrapper
    fn(*args, **kwargs)
  File "/root/applegenie/venv/lib/python3.12/site-packages/django/core/management/commands/runserver.py", line 125, in inner_run
    autoreload.raise_last_exception()
  File "/root/applegenie/venv/lib/python3.12/site-packages/django/utils/autoreload.py", line 87, in raise_last_exception
    raise _exception[1]
  File "/root/applegenie/venv/lib/python3.12/site-packages/django/core/management/__init__.py", line 394, in execute
    autoreload.check_errors(django.setup)()
  File "/root/applegenie/venv/lib/python3.12/site-packages/django/utils/autoreload.py", line 64, in wrapper
    fn(*args, **kwargs)
  File "/root/applegenie/venv/lib/python3.12/site-packages/django/__init__.py", line 24, in setup
    apps.populate(settings.INSTALLED_APPS)
  File "/root/applegenie/venv/lib/python3.12/site-packages/django/apps/registry.py", line 116, in populate
    app_config.import_models()
  File "/root/applegenie/venv/lib/python3.12/site-packages/django/apps/config.py", line 269, in import_models
    self.models_module = import_module(models_module_name)
                         ^^^^^^^^^^^^^^^^^^^^^^^^^^^^^^^^^
  File "/usr/lib/python3.12/importlib/__init__.py", line 90, in import_module
    return _bootstrap._gcd_import(name[level:], package, level)
           ^^^^^^^^^^^^^^^^^^^^^^^^^^^^^^^^^^^^^^^^^^^^^^^^^^^^
  File "<frozen importlib._bootstrap>", line 1387, in _gcd_import
  File "<frozen importlib._bootstrap>", line 1360, in _find_and_load
  File "<frozen importlib._bootstrap>", line 1331, in _find_and_load_unlocked
  File "<frozen importlib._bootstrap>", line 935, in _load_unlocked
  File "<frozen importlib._bootstrap_external>", line 991, in exec_module
  File "<frozen importlib._bootstrap_external>", line 1129, in get_code
  File "<frozen importlib._bootstrap_external>", line 1059, in source_to_code
  File "<frozen importlib._bootstrap>", line 488, in _call_with_frames_removed
  File "/root/applegenie/core_app_root/human_attributes/models.py", line 8
    "S": "Small",
       ^
SyntaxError: invalid syntax
/root/applegenie/core_app_root/human_attributes/models.py changed, reloading.
Watching for file changes with StatReloader
Exception in thread django-main-thread:
Traceback (most recent call last):
  File "/usr/lib/python3.12/threading.py", line 1073, in _bootstrap_inner
    self.run()
  File "/usr/lib/python3.12/threading.py", line 1010, in run
    self._target(*self._args, **self._kwargs)
  File "/root/applegenie/venv/lib/python3.12/site-packages/django/utils/autoreload.py", line 64, in wrapper
    fn(*args, **kwargs)
  File "/root/applegenie/venv/lib/python3.12/site-packages/django/core/management/commands/runserver.py", line 125, in inner_run
    autoreload.raise_last_exception()
  File "/root/applegenie/venv/lib/python3.12/site-packages/django/utils/autoreload.py", line 87, in raise_last_exception
    raise _exception[1]
  File "/root/applegenie/venv/lib/python3.12/site-packages/django/core/management/__init__.py", line 394, in execute
    autoreload.check_errors(django.setup)()
  File "/root/applegenie/venv/lib/python3.12/site-packages/django/utils/autoreload.py", line 64, in wrapper
    fn(*args, **kwargs)
  File "/root/applegenie/venv/lib/python3.12/site-packages/django/__init__.py", line 24, in setup
    apps.populate(settings.INSTALLED_APPS)
  File "/root/applegenie/venv/lib/python3.12/site-packages/django/apps/registry.py", line 116, in populate
    app_config.import_models()
  File "/root/applegenie/venv/lib/python3.12/site-packages/django/apps/config.py", line 269, in import_models
    self.models_module = import_module(models_module_name)
                         ^^^^^^^^^^^^^^^^^^^^^^^^^^^^^^^^^
  File "/usr/lib/python3.12/importlib/__init__.py", line 90, in import_module
    return _bootstrap._gcd_import(name[level:], package, level)
           ^^^^^^^^^^^^^^^^^^^^^^^^^^^^^^^^^^^^^^^^^^^^^^^^^^^^
  File "<frozen importlib._bootstrap>", line 1387, in _gcd_import
  File "<frozen importlib._bootstrap>", line 1360, in _find_and_load
  File "<frozen importlib._bootstrap>", line 1331, in _find_and_load_unlocked
  File "<frozen importlib._bootstrap>", line 935, in _load_unlocked
  File "<frozen importlib._bootstrap_external>", line 991, in exec_module
  File "<frozen importlib._bootstrap_external>", line 1129, in get_code
  File "<frozen importlib._bootstrap_external>", line 1059, in source_to_code
  File "<frozen importlib._bootstrap>", line 488, in _call_with_frames_removed
  File "/root/applegenie/core_app_root/human_attributes/models.py", line 5
    skin_color_types=(())"G":"Gray","W":"White","B":"Black"}
                                                           ^
SyntaxError: unmatched '}'
/root/applegenie/core_app_root/human_attributes/models.py changed, reloading.
Watching for file changes with StatReloader
Exception in thread django-main-thread:
Traceback (most recent call last):
  File "/usr/lib/python3.12/threading.py", line 1073, in _bootstrap_inner
    self.run()
  File "/usr/lib/python3.12/threading.py", line 1010, in run
    self._target(*self._args, **self._kwargs)
  File "/root/applegenie/venv/lib/python3.12/site-packages/django/utils/autoreload.py", line 64, in wrapper
    fn(*args, **kwargs)
  File "/root/applegenie/venv/lib/python3.12/site-packages/django/core/management/commands/runserver.py", line 125, in inner_run
    autoreload.raise_last_exception()
  File "/root/applegenie/venv/lib/python3.12/site-packages/django/utils/autoreload.py", line 87, in raise_last_exception
    raise _exception[1]
  File "/root/applegenie/venv/lib/python3.12/site-packages/django/core/management/__init__.py", line 394, in execute
    autoreload.check_errors(django.setup)()
  File "/root/applegenie/venv/lib/python3.12/site-packages/django/utils/autoreload.py", line 64, in wrapper
    fn(*args, **kwargs)
  File "/root/applegenie/venv/lib/python3.12/site-packages/django/__init__.py", line 24, in setup
    apps.populate(settings.INSTALLED_APPS)
  File "/root/applegenie/venv/lib/python3.12/site-packages/django/apps/registry.py", line 116, in populate
    app_config.import_models()
  File "/root/applegenie/venv/lib/python3.12/site-packages/django/apps/config.py", line 269, in import_models
    self.models_module = import_module(models_module_name)
                         ^^^^^^^^^^^^^^^^^^^^^^^^^^^^^^^^^
  File "/usr/lib/python3.12/importlib/__init__.py", line 90, in import_module
    return _bootstrap._gcd_import(name[level:], package, level)
           ^^^^^^^^^^^^^^^^^^^^^^^^^^^^^^^^^^^^^^^^^^^^^^^^^^^^
  File "<frozen importlib._bootstrap>", line 1387, in _gcd_import
  File "<frozen importlib._bootstrap>", line 1360, in _find_and_load
  File "<frozen importlib._bootstrap>", line 1331, in _find_and_load_unlocked
  File "<frozen importlib._bootstrap>", line 935, in _load_unlocked
  File "<frozen importlib._bootstrap_external>", line 991, in exec_module
  File "<frozen importlib._bootstrap_external>", line 1129, in get_code
  File "<frozen importlib._bootstrap_external>", line 1059, in source_to_code
  File "<frozen importlib._bootstrap>", line 488, in _call_with_frames_removed
  File "/root/applegenie/core_app_root/human_attributes/models.py", line 5
    skin_color_types=(("G":"Gray","W":"White","B":"Black"}
                                                         ^
SyntaxError: closing parenthesis '}' does not match opening parenthesis '('
/root/applegenie/core_app_root/human_attributes/models.py changed, reloading.
Watching for file changes with StatReloader
Exception in thread django-main-thread:
Traceback (most recent call last):
  File "/usr/lib/python3.12/threading.py", line 1073, in _bootstrap_inner
    self.run()
  File "/usr/lib/python3.12/threading.py", line 1010, in run
    self._target(*self._args, **self._kwargs)
  File "/root/applegenie/venv/lib/python3.12/site-packages/django/utils/autoreload.py", line 64, in wrapper
    fn(*args, **kwargs)
  File "/root/applegenie/venv/lib/python3.12/site-packages/django/core/management/commands/runserver.py", line 125, in inner_run
    autoreload.raise_last_exception()
  File "/root/applegenie/venv/lib/python3.12/site-packages/django/utils/autoreload.py", line 87, in raise_last_exception
    raise _exception[1]
  File "/root/applegenie/venv/lib/python3.12/site-packages/django/core/management/__init__.py", line 394, in execute
    autoreload.check_errors(django.setup)()
  File "/root/applegenie/venv/lib/python3.12/site-packages/django/utils/autoreload.py", line 64, in wrapper
    fn(*args, **kwargs)
  File "/root/applegenie/venv/lib/python3.12/site-packages/django/__init__.py", line 24, in setup
    apps.populate(settings.INSTALLED_APPS)
  File "/root/applegenie/venv/lib/python3.12/site-packages/django/apps/registry.py", line 116, in populate
    app_config.import_models()
  File "/root/applegenie/venv/lib/python3.12/site-packages/django/apps/config.py", line 269, in import_models
    self.models_module = import_module(models_module_name)
                         ^^^^^^^^^^^^^^^^^^^^^^^^^^^^^^^^^
  File "/usr/lib/python3.12/importlib/__init__.py", line 90, in import_module
    return _bootstrap._gcd_import(name[level:], package, level)
           ^^^^^^^^^^^^^^^^^^^^^^^^^^^^^^^^^^^^^^^^^^^^^^^^^^^^
  File "<frozen importlib._bootstrap>", line 1387, in _gcd_import
  File "<frozen importlib._bootstrap>", line 1360, in _find_and_load
  File "<frozen importlib._bootstrap>", line 1331, in _find_and_load_unlocked
  File "<frozen importlib._bootstrap>", line 935, in _load_unlocked
  File "<frozen importlib._bootstrap_external>", line 991, in exec_module
  File "<frozen importlib._bootstrap_external>", line 1129, in get_code
  File "<frozen importlib._bootstrap_external>", line 1059, in source_to_code
  File "<frozen importlib._bootstrap>", line 488, in _call_with_frames_removed
  File "/root/applegenie/core_app_root/human_attributes/models.py", line 5
    skin_color_types=(("G":"Gray","W":"White","B":"Black"))
                          ^
SyntaxError: invalid syntax
/root/applegenie/core_app_root/human_attributes/models.py changed, reloading.
Watching for file changes with StatReloader
Exception in thread django-main-thread:
Traceback (most recent call last):
  File "/usr/lib/python3.12/threading.py", line 1073, in _bootstrap_inner
    self.run()
  File "/usr/lib/python3.12/threading.py", line 1010, in run
    self._target(*self._args, **self._kwargs)
  File "/root/applegenie/venv/lib/python3.12/site-packages/django/utils/autoreload.py", line 64, in wrapper
    fn(*args, **kwargs)
  File "/root/applegenie/venv/lib/python3.12/site-packages/django/core/management/commands/runserver.py", line 125, in inner_run
    autoreload.raise_last_exception()
  File "/root/applegenie/venv/lib/python3.12/site-packages/django/utils/autoreload.py", line 87, in raise_last_exception
    raise _exception[1]
  File "/root/applegenie/venv/lib/python3.12/site-packages/django/core/management/__init__.py", line 394, in execute
    autoreload.check_errors(django.setup)()
  File "/root/applegenie/venv/lib/python3.12/site-packages/django/utils/autoreload.py", line 64, in wrapper
    fn(*args, **kwargs)
  File "/root/applegenie/venv/lib/python3.12/site-packages/django/__init__.py", line 24, in setup
    apps.populate(settings.INSTALLED_APPS)
  File "/root/applegenie/venv/lib/python3.12/site-packages/django/apps/registry.py", line 116, in populate
    app_config.import_models()
  File "/root/applegenie/venv/lib/python3.12/site-packages/django/apps/config.py", line 269, in import_models
    self.models_module = import_module(models_module_name)
                         ^^^^^^^^^^^^^^^^^^^^^^^^^^^^^^^^^
  File "/usr/lib/python3.12/importlib/__init__.py", line 90, in import_module
    return _bootstrap._gcd_import(name[level:], package, level)
           ^^^^^^^^^^^^^^^^^^^^^^^^^^^^^^^^^^^^^^^^^^^^^^^^^^^^
  File "<frozen importlib._bootstrap>", line 1387, in _gcd_import
  File "<frozen importlib._bootstrap>", line 1360, in _find_and_load
  File "<frozen importlib._bootstrap>", line 1331, in _find_and_load_unlocked
  File "<frozen importlib._bootstrap>", line 935, in _load_unlocked
  File "<frozen importlib._bootstrap_external>", line 991, in exec_module
  File "<frozen importlib._bootstrap_external>", line 1129, in get_code
  File "<frozen importlib._bootstrap_external>", line 1059, in source_to_code
  File "<frozen importlib._bootstrap>", line 488, in _call_with_frames_removed
  File "/root/applegenie/core_app_root/human_attributes/models.py", line 5
    skin_color_types=(("G":"Gray","W":"White","B":"Black"))
                          ^
SyntaxError: invalid syntax
/root/applegenie/core_app_root/human_attributes/models.py changed, reloading.
Watching for file changes with StatReloader
Exception in thread django-main-thread:
Traceback (most recent call last):
  File "/usr/lib/python3.12/threading.py", line 1073, in _bootstrap_inner
    self.run()
  File "/usr/lib/python3.12/threading.py", line 1010, in run
    self._target(*self._args, **self._kwargs)
  File "/root/applegenie/venv/lib/python3.12/site-packages/django/utils/autoreload.py", line 64, in wrapper
    fn(*args, **kwargs)
  File "/root/applegenie/venv/lib/python3.12/site-packages/django/core/management/commands/runserver.py", line 125, in inner_run
    autoreload.raise_last_exception()
  File "/root/applegenie/venv/lib/python3.12/site-packages/django/utils/autoreload.py", line 87, in raise_last_exception
    raise _exception[1]
  File "/root/applegenie/venv/lib/python3.12/site-packages/django/core/management/__init__.py", line 394, in execute
    autoreload.check_errors(django.setup)()
  File "/root/applegenie/venv/lib/python3.12/site-packages/django/utils/autoreload.py", line 64, in wrapper
    fn(*args, **kwargs)
  File "/root/applegenie/venv/lib/python3.12/site-packages/django/__init__.py", line 24, in setup
    apps.populate(settings.INSTALLED_APPS)
  File "/root/applegenie/venv/lib/python3.12/site-packages/django/apps/registry.py", line 116, in populate
    app_config.import_models()
  File "/root/applegenie/venv/lib/python3.12/site-packages/django/apps/config.py", line 269, in import_models
    self.models_module = import_module(models_module_name)
                         ^^^^^^^^^^^^^^^^^^^^^^^^^^^^^^^^^
  File "/usr/lib/python3.12/importlib/__init__.py", line 90, in import_module
    return _bootstrap._gcd_import(name[level:], package, level)
           ^^^^^^^^^^^^^^^^^^^^^^^^^^^^^^^^^^^^^^^^^^^^^^^^^^^^
  File "<frozen importlib._bootstrap>", line 1387, in _gcd_import
  File "<frozen importlib._bootstrap>", line 1360, in _find_and_load
  File "<frozen importlib._bootstrap>", line 1331, in _find_and_load_unlocked
  File "<frozen importlib._bootstrap>", line 935, in _load_unlocked
  File "<frozen importlib._bootstrap_external>", line 991, in exec_module
  File "<frozen importlib._bootstrap_external>", line 1129, in get_code
  File "<frozen importlib._bootstrap_external>", line 1059, in source_to_code
  File "<frozen importlib._bootstrap>", line 488, in _call_with_frames_removed
  File "/root/applegenie/core_app_root/human_attributes/models.py", line 5
    skin_color_types=(("G":"Gray","W":"White","B":"Black"))
                          ^
SyntaxError: invalid syntax
/root/applegenie/core_app_root/human_attributes/models.py changed, reloading.
Watching for file changes with StatReloader
Exception in thread django-main-thread:
Traceback (most recent call last):
  File "/usr/lib/python3.12/threading.py", line 1073, in _bootstrap_inner
    self.run()
  File "/usr/lib/python3.12/threading.py", line 1010, in run
    self._target(*self._args, **self._kwargs)
  File "/root/applegenie/venv/lib/python3.12/site-packages/django/utils/autoreload.py", line 64, in wrapper
    fn(*args, **kwargs)
  File "/root/applegenie/venv/lib/python3.12/site-packages/django/core/management/commands/runserver.py", line 125, in inner_run
    autoreload.raise_last_exception()
  File "/root/applegenie/venv/lib/python3.12/site-packages/django/utils/autoreload.py", line 87, in raise_last_exception
    raise _exception[1]
  File "/root/applegenie/venv/lib/python3.12/site-packages/django/core/management/__init__.py", line 394, in execute
    autoreload.check_errors(django.setup)()
  File "/root/applegenie/venv/lib/python3.12/site-packages/django/utils/autoreload.py", line 64, in wrapper
    fn(*args, **kwargs)
  File "/root/applegenie/venv/lib/python3.12/site-packages/django/__init__.py", line 24, in setup
    apps.populate(settings.INSTALLED_APPS)
  File "/root/applegenie/venv/lib/python3.12/site-packages/django/apps/registry.py", line 116, in populate
    app_config.import_models()
  File "/root/applegenie/venv/lib/python3.12/site-packages/django/apps/config.py", line 269, in import_models
    self.models_module = import_module(models_module_name)
                         ^^^^^^^^^^^^^^^^^^^^^^^^^^^^^^^^^
  File "/usr/lib/python3.12/importlib/__init__.py", line 90, in import_module
    return _bootstrap._gcd_import(name[level:], package, level)
           ^^^^^^^^^^^^^^^^^^^^^^^^^^^^^^^^^^^^^^^^^^^^^^^^^^^^
  File "<frozen importlib._bootstrap>", line 1387, in _gcd_import
  File "<frozen importlib._bootstrap>", line 1360, in _find_and_load
  File "<frozen importlib._bootstrap>", line 1331, in _find_and_load_unlocked
  File "<frozen importlib._bootstrap>", line 935, in _load_unlocked
  File "<frozen importlib._bootstrap_external>", line 991, in exec_module
  File "<frozen importlib._bootstrap_external>", line 1129, in get_code
  File "<frozen importlib._bootstrap_external>", line 1059, in source_to_code
  File "<frozen importlib._bootstrap>", line 488, in _call_with_frames_removed
  File "/root/applegenie/core_app_root/human_attributes/models.py", line 5
    skin_color_types=(("G":"Gray","W":"White","B":"Black"))
                          ^
SyntaxError: invalid syntax
/root/applegenie/core_app_root/human_attributes/models.py changed, reloading.
Watching for file changes with StatReloader
Exception in thread django-main-thread:
Traceback (most recent call last):
  File "/usr/lib/python3.12/threading.py", line 1073, in _bootstrap_inner
    self.run()
  File "/usr/lib/python3.12/threading.py", line 1010, in run
    self._target(*self._args, **self._kwargs)
  File "/root/applegenie/venv/lib/python3.12/site-packages/django/utils/autoreload.py", line 64, in wrapper
    fn(*args, **kwargs)
  File "/root/applegenie/venv/lib/python3.12/site-packages/django/core/management/commands/runserver.py", line 125, in inner_run
    autoreload.raise_last_exception()
  File "/root/applegenie/venv/lib/python3.12/site-packages/django/utils/autoreload.py", line 87, in raise_last_exception
    raise _exception[1]
  File "/root/applegenie/venv/lib/python3.12/site-packages/django/core/management/__init__.py", line 394, in execute
    autoreload.check_errors(django.setup)()
  File "/root/applegenie/venv/lib/python3.12/site-packages/django/utils/autoreload.py", line 64, in wrapper
    fn(*args, **kwargs)
  File "/root/applegenie/venv/lib/python3.12/site-packages/django/__init__.py", line 24, in setup
    apps.populate(settings.INSTALLED_APPS)
  File "/root/applegenie/venv/lib/python3.12/site-packages/django/apps/registry.py", line 116, in populate
    app_config.import_models()
  File "/root/applegenie/venv/lib/python3.12/site-packages/django/apps/config.py", line 269, in import_models
    self.models_module = import_module(models_module_name)
                         ^^^^^^^^^^^^^^^^^^^^^^^^^^^^^^^^^
  File "/usr/lib/python3.12/importlib/__init__.py", line 90, in import_module
    return _bootstrap._gcd_import(name[level:], package, level)
           ^^^^^^^^^^^^^^^^^^^^^^^^^^^^^^^^^^^^^^^^^^^^^^^^^^^^
  File "<frozen importlib._bootstrap>", line 1387, in _gcd_import
  File "<frozen importlib._bootstrap>", line 1360, in _find_and_load
  File "<frozen importlib._bootstrap>", line 1331, in _find_and_load_unlocked
  File "<frozen importlib._bootstrap>", line 935, in _load_unlocked
  File "<frozen importlib._bootstrap_external>", line 991, in exec_module
  File "<frozen importlib._bootstrap_external>", line 1129, in get_code
  File "<frozen importlib._bootstrap_external>", line 1059, in source_to_code
  File "<frozen importlib._bootstrap>", line 488, in _call_with_frames_removed
  File "/root/applegenie/core_app_root/human_attributes/models.py", line 5
    skin_color_types=(("G":"Gray","W":"White","B":"Black"))
                          ^
SyntaxError: invalid syntax
/root/applegenie/core_app_root/human_attributes/models.py changed, reloading.
Watching for file changes with StatReloader
Exception in thread django-main-thread:
Traceback (most recent call last):
  File "/usr/lib/python3.12/threading.py", line 1073, in _bootstrap_inner
    self.run()
  File "/usr/lib/python3.12/threading.py", line 1010, in run
    self._target(*self._args, **self._kwargs)
  File "/root/applegenie/venv/lib/python3.12/site-packages/django/utils/autoreload.py", line 64, in wrapper
    fn(*args, **kwargs)
  File "/root/applegenie/venv/lib/python3.12/site-packages/django/core/management/commands/runserver.py", line 125, in inner_run
    autoreload.raise_last_exception()
  File "/root/applegenie/venv/lib/python3.12/site-packages/django/utils/autoreload.py", line 87, in raise_last_exception
    raise _exception[1]
  File "/root/applegenie/venv/lib/python3.12/site-packages/django/core/management/__init__.py", line 394, in execute
    autoreload.check_errors(django.setup)()
  File "/root/applegenie/venv/lib/python3.12/site-packages/django/utils/autoreload.py", line 64, in wrapper
    fn(*args, **kwargs)
  File "/root/applegenie/venv/lib/python3.12/site-packages/django/__init__.py", line 24, in setup
    apps.populate(settings.INSTALLED_APPS)
  File "/root/applegenie/venv/lib/python3.12/site-packages/django/apps/registry.py", line 116, in populate
    app_config.import_models()
  File "/root/applegenie/venv/lib/python3.12/site-packages/django/apps/config.py", line 269, in import_models
    self.models_module = import_module(models_module_name)
                         ^^^^^^^^^^^^^^^^^^^^^^^^^^^^^^^^^
  File "/usr/lib/python3.12/importlib/__init__.py", line 90, in import_module
    return _bootstrap._gcd_import(name[level:], package, level)
           ^^^^^^^^^^^^^^^^^^^^^^^^^^^^^^^^^^^^^^^^^^^^^^^^^^^^
  File "<frozen importlib._bootstrap>", line 1387, in _gcd_import
  File "<frozen importlib._bootstrap>", line 1360, in _find_and_load
  File "<frozen importlib._bootstrap>", line 1331, in _find_and_load_unlocked
  File "<frozen importlib._bootstrap>", line 935, in _load_unlocked
  File "<frozen importlib._bootstrap_external>", line 991, in exec_module
  File "<frozen importlib._bootstrap_external>", line 1129, in get_code
  File "<frozen importlib._bootstrap_external>", line 1059, in source_to_code
  File "<frozen importlib._bootstrap>", line 488, in _call_with_frames_removed
  File "/root/applegenie/core_app_root/human_attributes/models.py", line 8
    "S": "Small",
       ^
SyntaxError: invalid syntax
/root/applegenie/core_app_root/human_attributes/models.py changed, reloading.
Watching for file changes with StatReloader
Exception in thread django-main-thread:
Traceback (most recent call last):
  File "/usr/lib/python3.12/threading.py", line 1073, in _bootstrap_inner
    self.run()
  File "/usr/lib/python3.12/threading.py", line 1010, in run
    self._target(*self._args, **self._kwargs)
  File "/root/applegenie/venv/lib/python3.12/site-packages/django/utils/autoreload.py", line 64, in wrapper
    fn(*args, **kwargs)
  File "/root/applegenie/venv/lib/python3.12/site-packages/django/core/management/commands/runserver.py", line 125, in inner_run
    autoreload.raise_last_exception()
  File "/root/applegenie/venv/lib/python3.12/site-packages/django/utils/autoreload.py", line 87, in raise_last_exception
    raise _exception[1]
  File "/root/applegenie/venv/lib/python3.12/site-packages/django/core/management/__init__.py", line 394, in execute
    autoreload.check_errors(django.setup)()
  File "/root/applegenie/venv/lib/python3.12/site-packages/django/utils/autoreload.py", line 64, in wrapper
    fn(*args, **kwargs)
  File "/root/applegenie/venv/lib/python3.12/site-packages/django/__init__.py", line 24, in setup
    apps.populate(settings.INSTALLED_APPS)
  File "/root/applegenie/venv/lib/python3.12/site-packages/django/apps/registry.py", line 116, in populate
    app_config.import_models()
  File "/root/applegenie/venv/lib/python3.12/site-packages/django/apps/config.py", line 269, in import_models
    self.models_module = import_module(models_module_name)
                         ^^^^^^^^^^^^^^^^^^^^^^^^^^^^^^^^^
  File "/usr/lib/python3.12/importlib/__init__.py", line 90, in import_module
    return _bootstrap._gcd_import(name[level:], package, level)
           ^^^^^^^^^^^^^^^^^^^^^^^^^^^^^^^^^^^^^^^^^^^^^^^^^^^^
  File "<frozen importlib._bootstrap>", line 1387, in _gcd_import
  File "<frozen importlib._bootstrap>", line 1360, in _find_and_load
  File "<frozen importlib._bootstrap>", line 1331, in _find_and_load_unlocked
  File "<frozen importlib._bootstrap>", line 935, in _load_unlocked
  File "<frozen importlib._bootstrap_external>", line 995, in exec_module
  File "<frozen importlib._bootstrap>", line 488, in _call_with_frames_removed
  File "/root/applegenie/core_app_root/human_attributes/models.py", line 4, in <module>
    class HumanQualities(models.Model):
  File "/root/applegenie/core_app_root/human_attributes/models.py", line 6, in HumanQualities
    skin_color=models.CharField(null=True,blank=True,max_length=500,choices=skin_color_types)
                                                                            ^^^^^^^^^^^^^^^^
NameError: name 'skin_color_types' is not defined
/root/applegenie/core_app_root/human_attributes/models.py changed, reloading.
Watching for file changes with StatReloader
Exception in thread django-main-thread:
Traceback (most recent call last):
  File "/usr/lib/python3.12/threading.py", line 1073, in _bootstrap_inner
    self.run()
  File "/usr/lib/python3.12/threading.py", line 1010, in run
    self._target(*self._args, **self._kwargs)
  File "/root/applegenie/venv/lib/python3.12/site-packages/django/utils/autoreload.py", line 64, in wrapper
    fn(*args, **kwargs)
  File "/root/applegenie/venv/lib/python3.12/site-packages/django/core/management/commands/runserver.py", line 125, in inner_run
    autoreload.raise_last_exception()
  File "/root/applegenie/venv/lib/python3.12/site-packages/django/utils/autoreload.py", line 87, in raise_last_exception
    raise _exception[1]
  File "/root/applegenie/venv/lib/python3.12/site-packages/django/core/management/__init__.py", line 394, in execute
    autoreload.check_errors(django.setup)()
  File "/root/applegenie/venv/lib/python3.12/site-packages/django/utils/autoreload.py", line 64, in wrapper
    fn(*args, **kwargs)
  File "/root/applegenie/venv/lib/python3.12/site-packages/django/__init__.py", line 24, in setup
    apps.populate(settings.INSTALLED_APPS)
  File "/root/applegenie/venv/lib/python3.12/site-packages/django/apps/registry.py", line 116, in populate
    app_config.import_models()
  File "/root/applegenie/venv/lib/python3.12/site-packages/django/apps/config.py", line 269, in import_models
    self.models_module = import_module(models_module_name)
                         ^^^^^^^^^^^^^^^^^^^^^^^^^^^^^^^^^
  File "/usr/lib/python3.12/importlib/__init__.py", line 90, in import_module
    return _bootstrap._gcd_import(name[level:], package, level)
           ^^^^^^^^^^^^^^^^^^^^^^^^^^^^^^^^^^^^^^^^^^^^^^^^^^^^
  File "<frozen importlib._bootstrap>", line 1387, in _gcd_import
  File "<frozen importlib._bootstrap>", line 1360, in _find_and_load
  File "<frozen importlib._bootstrap>", line 1331, in _find_and_load_unlocked
  File "<frozen importlib._bootstrap>", line 935, in _load_unlocked
  File "<frozen importlib._bootstrap_external>", line 995, in exec_module
  File "<frozen importlib._bootstrap>", line 488, in _call_with_frames_removed
  File "/root/applegenie/core_app_root/human_attributes/models.py", line 4, in <module>
    class HumanQualities(models.Model):
  File "/root/applegenie/core_app_root/human_attributes/models.py", line 12, in HumanQualities
    shirt_size = models.CharField(max_length=1, choices=body_size)
                                                        ^^^^^^^^^
NameError: name 'body_size' is not defined
/root/applegenie/core_app_root/human_attributes/models.py changed, reloading.
Watching for file changes with StatReloader
Exception in thread django-main-thread:
Traceback (most recent call last):
  File "/usr/lib/python3.12/threading.py", line 1073, in _bootstrap_inner
    self.run()
  File "/usr/lib/python3.12/threading.py", line 1010, in run
    self._target(*self._args, **self._kwargs)
  File "/root/applegenie/venv/lib/python3.12/site-packages/django/utils/autoreload.py", line 64, in wrapper
    fn(*args, **kwargs)
  File "/root/applegenie/venv/lib/python3.12/site-packages/django/core/management/commands/runserver.py", line 136, in inner_run
    self.check_migrations()
  File "/root/applegenie/venv/lib/python3.12/site-packages/django/core/management/base.py", line 574, in check_migrations
    executor = MigrationExecutor(connections[DEFAULT_DB_ALIAS])
               ^^^^^^^^^^^^^^^^^^^^^^^^^^^^^^^^^^^^^^^^^^^^^^^^
  File "/root/applegenie/venv/lib/python3.12/site-packages/django/db/migrations/executor.py", line 18, in __init__
    self.loader = MigrationLoader(self.connection)
                  ^^^^^^^^^^^^^^^^^^^^^^^^^^^^^^^^
  File "/root/applegenie/venv/lib/python3.12/site-packages/django/db/migrations/loader.py", line 58, in __init__
    self.build_graph()
  File "/root/applegenie/venv/lib/python3.12/site-packages/django/db/migrations/loader.py", line 229, in build_graph
    self.load_disk()
  File "/root/applegenie/venv/lib/python3.12/site-packages/django/db/migrations/loader.py", line 120, in load_disk
    migration_module = import_module(migration_path)
                       ^^^^^^^^^^^^^^^^^^^^^^^^^^^^^
  File "/usr/lib/python3.12/importlib/__init__.py", line 90, in import_module
    return _bootstrap._gcd_import(name[level:], package, level)
           ^^^^^^^^^^^^^^^^^^^^^^^^^^^^^^^^^^^^^^^^^^^^^^^^^^^^
  File "<frozen importlib._bootstrap>", line 1387, in _gcd_import
  File "<frozen importlib._bootstrap>", line 1360, in _find_and_load
  File "<frozen importlib._bootstrap>", line 1331, in _find_and_load_unlocked
  File "<frozen importlib._bootstrap>", line 935, in _load_unlocked
  File "<frozen importlib._bootstrap_external>", line 995, in exec_module
  File "<frozen importlib._bootstrap>", line 488, in _call_with_frames_removed
  File "/root/applegenie/core_app_root/apple_gifting/migrations/0001_initial.py", line 6, in <module>
    class Migration(migrations.Migration):
  File "/root/applegenie/core_app_root/apple_gifting/migrations/0001_initial.py", line 24, in Migration
    ("number_of_apples", models.IntegerField(db_default=0, null=True)),
                         ^^^^^^^^^^^^^^^^^^^^^^^^^^^^^^^^^^^^^^^^^^^^
TypeError: Field.__init__() got an unexpected keyword argument 'db_default'
/root/applegenie/core_app_root/human_attributes/models.py changed, reloading.
Performing system checks...

System check identified no issues (0 silenced).
Watching for file changes with StatReloader
Exception in thread django-main-thread:
Traceback (most recent call last):
  File "/usr/lib/python3.12/threading.py", line 1073, in _bootstrap_inner
    self.run()
  File "/usr/lib/python3.12/threading.py", line 1010, in run
    self._target(*self._args, **self._kwargs)
  File "/root/applegenie/venv/lib/python3.12/site-packages/django/utils/autoreload.py", line 64, in wrapper
    fn(*args, **kwargs)
  File "/root/applegenie/venv/lib/python3.12/site-packages/django/core/management/commands/runserver.py", line 136, in inner_run
    self.check_migrations()
  File "/root/applegenie/venv/lib/python3.12/site-packages/django/core/management/base.py", line 574, in check_migrations
    executor = MigrationExecutor(connections[DEFAULT_DB_ALIAS])
               ^^^^^^^^^^^^^^^^^^^^^^^^^^^^^^^^^^^^^^^^^^^^^^^^
  File "/root/applegenie/venv/lib/python3.12/site-packages/django/db/migrations/executor.py", line 18, in __init__
    self.loader = MigrationLoader(self.connection)
                  ^^^^^^^^^^^^^^^^^^^^^^^^^^^^^^^^
  File "/root/applegenie/venv/lib/python3.12/site-packages/django/db/migrations/loader.py", line 58, in __init__
    self.build_graph()
  File "/root/applegenie/venv/lib/python3.12/site-packages/django/db/migrations/loader.py", line 229, in build_graph
    self.load_disk()
  File "/root/applegenie/venv/lib/python3.12/site-packages/django/db/migrations/loader.py", line 120, in load_disk
    migration_module = import_module(migration_path)
                       ^^^^^^^^^^^^^^^^^^^^^^^^^^^^^
  File "/usr/lib/python3.12/importlib/__init__.py", line 90, in import_module
    return _bootstrap._gcd_import(name[level:], package, level)
           ^^^^^^^^^^^^^^^^^^^^^^^^^^^^^^^^^^^^^^^^^^^^^^^^^^^^
  File "<frozen importlib._bootstrap>", line 1387, in _gcd_import
  File "<frozen importlib._bootstrap>", line 1360, in _find_and_load
  File "<frozen importlib._bootstrap>", line 1331, in _find_and_load_unlocked
  File "<frozen importlib._bootstrap>", line 935, in _load_unlocked
  File "<frozen importlib._bootstrap_external>", line 995, in exec_module
  File "<frozen importlib._bootstrap>", line 488, in _call_with_frames_removed
  File "/root/applegenie/core_app_root/apple_gifting/migrations/0001_initial.py", line 6, in <module>
    class Migration(migrations.Migration):
  File "/root/applegenie/core_app_root/apple_gifting/migrations/0001_initial.py", line 24, in Migration
    ("number_of_apples", models.IntegerField(db_default=0, null=True)),
                         ^^^^^^^^^^^^^^^^^^^^^^^^^^^^^^^^^^^^^^^^^^^^
TypeError: Field.__init__() got an unexpected keyword argument 'db_default'
/root/applegenie/core_app_root/apple_gifting/migrations/0001_initial.py changed, reloading.
Performing system checks...

System check identified no issues (0 silenced).
Watching for file changes with StatReloader
Watching for file changes with StatReloader
Error: That port is already in use.
Invalid HTTP_HOST header: '142.93.14.212:8000'. You may need to add '142.93.14.212' to ALLOWED_HOSTS.
Traceback (most recent call last):
  File "/root/applegenie/venv/lib/python3.12/site-packages/django/core/handlers/exception.py", line 55, in inner
    response = get_response(request)
               ^^^^^^^^^^^^^^^^^^^^^
  File "/root/applegenie/venv/lib/python3.12/site-packages/django/utils/deprecation.py", line 133, in __call__
    response = self.process_request(request)
               ^^^^^^^^^^^^^^^^^^^^^^^^^^^^^
  File "/root/applegenie/venv/lib/python3.12/site-packages/django/middleware/common.py", line 48, in process_request
    host = request.get_host()
           ^^^^^^^^^^^^^^^^^^
  File "/root/applegenie/venv/lib/python3.12/site-packages/django/http/request.py", line 150, in get_host
    raise DisallowedHost(msg)
django.core.exceptions.DisallowedHost: Invalid HTTP_HOST header: '142.93.14.212:8000'. You may need to add '142.93.14.212' to ALLOWED_HOSTS.
Bad Request: /
[03/Jun/2024 02:03:04] "GET / HTTP/1.1" 400 67937
Invalid HTTP_HOST header: '142.93.14.212:8000'. You may need to add '142.93.14.212' to ALLOWED_HOSTS.
Traceback (most recent call last):
  File "/root/applegenie/venv/lib/python3.12/site-packages/django/core/handlers/exception.py", line 55, in inner
    response = get_response(request)
               ^^^^^^^^^^^^^^^^^^^^^
  File "/root/applegenie/venv/lib/python3.12/site-packages/django/utils/deprecation.py", line 133, in __call__
    response = self.process_request(request)
               ^^^^^^^^^^^^^^^^^^^^^^^^^^^^^
  File "/root/applegenie/venv/lib/python3.12/site-packages/django/middleware/common.py", line 48, in process_request
    host = request.get_host()
           ^^^^^^^^^^^^^^^^^^
  File "/root/applegenie/venv/lib/python3.12/site-packages/django/http/request.py", line 150, in get_host
    raise DisallowedHost(msg)
django.core.exceptions.DisallowedHost: Invalid HTTP_HOST header: '142.93.14.212:8000'. You may need to add '142.93.14.212' to ALLOWED_HOSTS.
Bad Request: /favicon.ico
[03/Jun/2024 02:03:05] "GET /favicon.ico HTTP/1.1" 400 67994
Invalid HTTP_HOST header: '142.93.14.212:8000'. You may need to add '142.93.14.212' to ALLOWED_HOSTS.
Traceback (most recent call last):
  File "/root/applegenie/venv/lib/python3.12/site-packages/django/core/handlers/exception.py", line 55, in inner
    response = get_response(request)
               ^^^^^^^^^^^^^^^^^^^^^
  File "/root/applegenie/venv/lib/python3.12/site-packages/django/utils/deprecation.py", line 133, in __call__
    response = self.process_request(request)
               ^^^^^^^^^^^^^^^^^^^^^^^^^^^^^
  File "/root/applegenie/venv/lib/python3.12/site-packages/django/middleware/common.py", line 48, in process_request
    host = request.get_host()
           ^^^^^^^^^^^^^^^^^^
  File "/root/applegenie/venv/lib/python3.12/site-packages/django/http/request.py", line 150, in get_host
    raise DisallowedHost(msg)
django.core.exceptions.DisallowedHost: Invalid HTTP_HOST header: '142.93.14.212:8000'. You may need to add '142.93.14.212' to ALLOWED_HOSTS.
Bad Request: /
[03/Jun/2024 02:03:18] "GET / HTTP/1.1" 400 68074
Invalid HTTP_HOST header: '142.93.14.212:8000'. You may need to add '142.93.14.212' to ALLOWED_HOSTS.
Traceback (most recent call last):
  File "/root/applegenie/venv/lib/python3.12/site-packages/django/core/handlers/exception.py", line 55, in inner
    response = get_response(request)
               ^^^^^^^^^^^^^^^^^^^^^
  File "/root/applegenie/venv/lib/python3.12/site-packages/django/utils/deprecation.py", line 133, in __call__
    response = self.process_request(request)
               ^^^^^^^^^^^^^^^^^^^^^^^^^^^^^
  File "/root/applegenie/venv/lib/python3.12/site-packages/django/middleware/common.py", line 48, in process_request
    host = request.get_host()
           ^^^^^^^^^^^^^^^^^^
  File "/root/applegenie/venv/lib/python3.12/site-packages/django/http/request.py", line 150, in get_host
    raise DisallowedHost(msg)
django.core.exceptions.DisallowedHost: Invalid HTTP_HOST header: '142.93.14.212:8000'. You may need to add '142.93.14.212' to ALLOWED_HOSTS.
Bad Request: /favicon.ico
[03/Jun/2024 02:03:20] "GET /favicon.ico HTTP/1.1" 400 67994
Invalid HTTP_HOST header: '142.93.14.212:8000'. You may need to add '142.93.14.212' to ALLOWED_HOSTS.
Traceback (most recent call last):
  File "/root/applegenie/venv/lib/python3.12/site-packages/django/core/handlers/exception.py", line 55, in inner
    response = get_response(request)
               ^^^^^^^^^^^^^^^^^^^^^
  File "/root/applegenie/venv/lib/python3.12/site-packages/django/utils/deprecation.py", line 133, in __call__
    response = self.process_request(request)
               ^^^^^^^^^^^^^^^^^^^^^^^^^^^^^
  File "/root/applegenie/venv/lib/python3.12/site-packages/django/middleware/common.py", line 48, in process_request
    host = request.get_host()
           ^^^^^^^^^^^^^^^^^^
  File "/root/applegenie/venv/lib/python3.12/site-packages/django/http/request.py", line 150, in get_host
    raise DisallowedHost(msg)
django.core.exceptions.DisallowedHost: Invalid HTTP_HOST header: '142.93.14.212:8000'. You may need to add '142.93.14.212' to ALLOWED_HOSTS.
Bad Request: /api/docs/
[03/Jun/2024 02:03:38] "GET /api/docs/ HTTP/1.1" 400 68036
Invalid HTTP_HOST header: '142.93.14.212:8000'. You may need to add '142.93.14.212' to ALLOWED_HOSTS.
Traceback (most recent call last):
  File "/root/applegenie/venv/lib/python3.12/site-packages/django/core/handlers/exception.py", line 55, in inner
    response = get_response(request)
               ^^^^^^^^^^^^^^^^^^^^^
  File "/root/applegenie/venv/lib/python3.12/site-packages/django/utils/deprecation.py", line 133, in __call__
    response = self.process_request(request)
               ^^^^^^^^^^^^^^^^^^^^^^^^^^^^^
  File "/root/applegenie/venv/lib/python3.12/site-packages/django/middleware/common.py", line 48, in process_request
    host = request.get_host()
           ^^^^^^^^^^^^^^^^^^
  File "/root/applegenie/venv/lib/python3.12/site-packages/django/http/request.py", line 150, in get_host
    raise DisallowedHost(msg)
django.core.exceptions.DisallowedHost: Invalid HTTP_HOST header: '142.93.14.212:8000'. You may need to add '142.93.14.212' to ALLOWED_HOSTS.
Bad Request: /favicon.ico
[03/Jun/2024 02:03:39] "GET /favicon.ico HTTP/1.1" 400 68003
/root/applegenie/applegenie/settings.py changed, reloading.
/root/applegenie/applegenie/settings.py changed, reloading.
Performing system checks...

System check identified no issues (0 silenced).

You have 4 unapplied migration(s). Your project may not work properly until you apply the migrations for app(s): authtoken.
Run 'python manage.py migrate' to apply them.
June 03, 2024 - 02:01:19
Django version 4.2.13, using settings 'applegenie.settings'
Starting development server at http://142.93.14.212:8000/
Quit the server with CONTROL-C.

Watching for file changes with StatReloader
Watching for file changes with StatReloader
Error: That port is already in use.
/root/applegenie/applegenie/settings.py changed, reloading.
Performing system checks...

System check identified no issues (0 silenced).
June 03, 2024 - 02:04:27
Django version 4.2.13, using settings 'applegenie.settings'
Starting development server at http://142.93.14.212:8000/
Quit the server with CONTROL-C.

Watching for file changes with StatReloader
Watching for file changes with StatReloader
Error: That port is already in use.
[03/Jun/2024 02:04:37] "GET /api/docs/ HTTP/1.1" 200 2163
[03/Jun/2024 02:04:37] "GET /static/drf-yasg/style.css HTTP/1.1" 200 1047
[03/Jun/2024 02:04:37] "GET /static/drf-yasg/insQ.min.js HTTP/1.1" 200 2093
[03/Jun/2024 02:04:38] "GET /static/drf-yasg/swagger-ui-dist/swagger-ui.css HTTP/1.1" 200 145206
[03/Jun/2024 02:04:38] "GET /static/drf-yasg/immutable.min.js HTTP/1.1" 200 56904
[03/Jun/2024 02:04:38] "GET /static/drf-yasg/swagger-ui-init.js HTTP/1.1" 200 14964
[03/Jun/2024 02:04:38] "GET /static/drf-yasg/swagger-ui-dist/swagger-ui-standalone-preset.js HTTP/1.1" 200 322863
[03/Jun/2024 02:04:40] "GET /static/drf-yasg/swagger-ui-dist/swagger-ui-bundle.js HTTP/1.1" 200 1046583
[03/Jun/2024 02:04:41] "GET /api/docs/?format=openapi HTTP/1.1" 200 3301
[03/Jun/2024 02:04:41] "GET /static/drf-yasg/swagger-ui-dist/favicon-32x32.png HTTP/1.1" 200 628
[03/Jun/2024 02:04:42] "GET /api/docs/?format=openapi HTTP/1.1" 200 3301
/root/applegenie/core_app_root/human_attributes/models.py changed, reloading.
Performing system checks...

System check identified no issues (0 silenced).
June 03, 2024 - 02:04:32
Django version 4.2.13, using settings 'applegenie.settings'
Starting development server at http://142.93.14.212:8000/
Quit the server with CONTROL-C.

Watching for file changes with StatReloader
[03/Jun/2024 02:06:20] "GET /api/docs/ HTTP/1.1" 200 2163
[03/Jun/2024 02:06:21] "GET /static/drf-yasg/style.css HTTP/1.1" 304 0
[03/Jun/2024 02:06:21] "GET /static/drf-yasg/swagger-ui-dist/swagger-ui.css HTTP/1.1" 304 0
[03/Jun/2024 02:06:21] "GET /static/drf-yasg/swagger-ui-dist/swagger-ui-bundle.js HTTP/1.1" 304 0
[03/Jun/2024 02:06:22] "GET /static/drf-yasg/insQ.min.js HTTP/1.1" 304 0
[03/Jun/2024 02:06:22] "GET /static/drf-yasg/swagger-ui-dist/swagger-ui-standalone-preset.js HTTP/1.1" 304 0
[03/Jun/2024 02:06:22] "GET /static/drf-yasg/immutable.min.js HTTP/1.1" 304 0
[03/Jun/2024 02:06:22] "GET /static/drf-yasg/swagger-ui-init.js HTTP/1.1" 304 0
[03/Jun/2024 02:06:22] "GET /api/docs/?format=openapi HTTP/1.1" 200 3298
[03/Jun/2024 02:06:22] "GET /static/drf-yasg/swagger-ui-dist/favicon-32x32.png HTTP/1.1" 304 0
[03/Jun/2024 02:06:23] "GET /api/docs/?format=openapi HTTP/1.1" 200 3298
[03/Jun/2024 02:12:07] code 400, message Bad request version ('ú')
[03/Jun/2024 02:12:07] You're accessing the development server over HTTPS, but it only supports HTTP.
[03/Jun/2024 02:12:07] code 400, message Bad request version ('¾@{CÁ\x87ÔjÔV')
[03/Jun/2024 02:12:07] You're accessing the development server over HTTPS, but it only supports HTTP.
[03/Jun/2024 02:12:10] "GET /api/docs/ HTTP/1.1" 200 2163
[03/Jun/2024 02:12:10] "GET /static/drf-yasg/style.css HTTP/1.1" 200 1047
[03/Jun/2024 02:12:11] "GET /static/drf-yasg/insQ.min.js HTTP/1.1" 200 2093
[03/Jun/2024 02:12:11] "GET /static/drf-yasg/swagger-ui-init.js HTTP/1.1" 200 14964
[03/Jun/2024 02:12:11] "GET /static/drf-yasg/swagger-ui-dist/swagger-ui.css HTTP/1.1" 200 145206
[03/Jun/2024 02:12:11] "GET /static/drf-yasg/immutable.min.js HTTP/1.1" 200 56904
[03/Jun/2024 02:12:12] "GET /static/drf-yasg/swagger-ui-dist/swagger-ui-standalone-preset.js HTTP/1.1" 200 322863
[03/Jun/2024 02:12:12] "GET /static/drf-yasg/swagger-ui-dist/swagger-ui-bundle.js HTTP/1.1" 200 1046583
[03/Jun/2024 02:12:13] "GET /api/docs/?format=openapi HTTP/1.1" 200 3298
[03/Jun/2024 02:12:13] "GET /static/drf-yasg/swagger-ui-dist/favicon-32x32.png HTTP/1.1" 200 628
[03/Jun/2024 02:12:14] "GET /api/docs/?format=openapi HTTP/1.1" 200 3298
[03/Jun/2024 05:35:22] code 400, message Bad request version ('úú\x13\x01\x13\x02\x13\x03À+À/À,À0Ì©Ì¨À\x13À\x14\x00\x9c\x00\x9d\x00/\x005\x01\x00\x063\x1a\x1a\x00\x00\x00\x12\x00\x00\x00')
[03/Jun/2024 05:35:22] You're accessing the development server over HTTPS, but it only supports HTTP.
[03/Jun/2024 05:35:22] code 400, message Bad request syntax ('\x16\x03\x01\x07\x00\x01\x00\x06ü\x03\x03d3Ø!Çµ5*½')
[03/Jun/2024 05:35:22] You're accessing the development server over HTTPS, but it only supports HTTP.
[03/Jun/2024 05:35:23] code 400, message Bad request version ('´j\x8dHÑ\x93Ò\x9a\x18ÆZ\x88\x88ÛVÇéExK(H±G\x84$¤³\x89\x17\x95±')
[03/Jun/2024 05:35:23] You're accessing the development server over HTTPS, but it only supports HTTP.
[03/Jun/2024 05:35:23] code 400, message Bad request version ("'¨ùX\x90ï")
[03/Jun/2024 05:35:23] You're accessing the development server over HTTPS, but it only supports HTTP.
[03/Jun/2024 05:35:26] "GET /api/docs/ HTTP/1.1" 200 2163
[03/Jun/2024 05:35:27] "GET /static/drf-yasg/style.css HTTP/1.1" 200 1047
[03/Jun/2024 05:35:28] "GET /static/drf-yasg/swagger-ui-dist/swagger-ui.css HTTP/1.1" 200 145206
[03/Jun/2024 05:35:28] "GET /static/drf-yasg/insQ.min.js HTTP/1.1" 200 2093
[03/Jun/2024 05:35:28] "GET /static/drf-yasg/swagger-ui-init.js HTTP/1.1" 200 14964
[03/Jun/2024 05:35:28] "GET /static/drf-yasg/immutable.min.js HTTP/1.1" 200 56904
[03/Jun/2024 05:35:29] "GET /static/drf-yasg/swagger-ui-dist/swagger-ui-standalone-preset.js HTTP/1.1" 200 322863
[03/Jun/2024 05:35:29] "GET /static/drf-yasg/swagger-ui-dist/swagger-ui-bundle.js HTTP/1.1" 200 1046583
[03/Jun/2024 05:35:31] "GET /api/docs/?format=openapi HTTP/1.1" 200 3298
[03/Jun/2024 05:35:31] "GET /static/drf-yasg/swagger-ui-dist/favicon-32x32.png HTTP/1.1" 200 628
[03/Jun/2024 05:35:32] "GET /api/docs/?format=openapi HTTP/1.1" 200 3298
Not Found: /
[03/Jun/2024 05:44:39] "GET / HTTP/1.1" 404 3573
[03/Jun/2024 07:19:47] "GET /api/docs/ HTTP/1.1" 200 2163
[03/Jun/2024 07:19:48] "GET /static/drf-yasg/style.css HTTP/1.1" 200 1047
[03/Jun/2024 07:19:48] "GET /static/drf-yasg/insQ.min.js HTTP/1.1" 200 2093
[03/Jun/2024 07:19:48] "GET /static/drf-yasg/immutable.min.js HTTP/1.1" 200 56904
[03/Jun/2024 07:19:48] "GET /static/drf-yasg/swagger-ui-dist/swagger-ui.css HTTP/1.1" 200 145206
[03/Jun/2024 07:19:49] "GET /static/drf-yasg/swagger-ui-dist/swagger-ui-standalone-preset.js HTTP/1.1" 200 322863
[03/Jun/2024 07:19:49] "GET /static/drf-yasg/swagger-ui-init.js HTTP/1.1" 200 14964
[03/Jun/2024 07:19:49] "GET /static/drf-yasg/swagger-ui-dist/swagger-ui-bundle.js HTTP/1.1" 200 1046583
[03/Jun/2024 07:19:51] "GET /api/docs/?format=openapi HTTP/1.1" 200 3298
[03/Jun/2024 07:19:51] "GET /static/drf-yasg/swagger-ui-dist/favicon-32x32.png HTTP/1.1" 200 628
[03/Jun/2024 07:19:52] "GET /api/docs/?format=openapi HTTP/1.1" 200 3298
[03/Jun/2024 07:31:54] code 400, message Bad request version ('À\x14À')
[03/Jun/2024 07:31:54] You're accessing the development server over HTTPS, but it only supports HTTP.
[03/Jun/2024 07:31:54] code 400, message Bad request version ('À\x14À')
[03/Jun/2024 07:31:54] You're accessing the development server over HTTPS, but it only supports HTTP.
Not Found: /
[03/Jun/2024 07:31:54] "GET / HTTP/1.1" 404 3573
[03/Jun/2024 07:31:54] code 400, message Bad request version ('À\x14À')
[03/Jun/2024 07:31:54] You're accessing the development server over HTTPS, but it only supports HTTP.
Not Found: /login
[03/Jun/2024 07:31:54] "GET /login HTTP/1.1" 404 3610
[03/Jun/2024 07:40:15] "GET /api/docs/?format=openapi HTTP/1.1" 200 3298
[03/Jun/2024 07:40:16] "GET /api/docs/?format=openapi HTTP/1.1" 200 3298
Not Found: /
[03/Jun/2024 08:12:33] "GET / HTTP/1.1" 404 3581
Not Found: /
[03/Jun/2024 08:13:55] "GET / HTTP/1.1" 404 3581
Not Found: /
[03/Jun/2024 08:47:52] "GET / HTTP/1.1" 404 3573
Not Found: /favicon.ico
[03/Jun/2024 08:48:13] "GET /favicon.ico HTTP/1.1" 404 3634
Not Found: /http:/api.ipify.org/
[03/Jun/2024 08:48:17] "GET http://api.ipify.org/?format=json HTTP/1.1" 404 1919
Not Found: /www.shadowserver.org:443
[03/Jun/2024 08:48:20] "CONNECT www.shadowserver.org:443 HTTP/1.1" 404 1928
Not Found: /
[03/Jun/2024 12:06:36] "GET / HTTP/1.1" 404 3573
[03/Jun/2024 12:52:39,300] - Broken pipe from ('167.94.146.56', 50434)
Not Found: /
[03/Jun/2024 12:52:42] "GET / HTTP/1.1" 404 3573
[03/Jun/2024 12:52:42,489] - Broken pipe from ('167.94.146.56', 50450)
Not Found: /
[03/Jun/2024 12:52:45] "GET / HTTP/1.1" 404 3573
[03/Jun/2024 12:52:45] code 505, message Invalid HTTP version (2.0)
[03/Jun/2024 12:52:45] "PRI * HTTP/2.0" 505 -
Not Found: /
[03/Jun/2024 12:55:19] "GET / HTTP/1.1" 404 3573
[03/Jun/2024 14:57:34] code 400, message Bad request syntax ('\x01\x01æ')
[03/Jun/2024 14:57:34] "æ" 400 -
[03/Jun/2024 15:42:30] code 400, message Bad request version ('\x00\x9eÌ¨Ìª\x003\x00=\x00\x16À')
[03/Jun/2024 15:42:30] You're accessing the development server over HTTPS, but it only supports HTTP.
Not Found: /
[03/Jun/2024 15:42:42] "GET / HTTP/1.1" 404 3573
Not Found: /favicon.ico
[03/Jun/2024 15:43:00] "GET /favicon.ico HTTP/1.1" 404 3634
Not Found: /robots.txt
[03/Jun/2024 15:43:01] "GET /robots.txt HTTP/1.1" 404 3630
Not Found: /sitemap.xml
[03/Jun/2024 15:43:02] "GET /sitemap.xml HTTP/1.1" 404 3634
/root/applegenie/core_app_root/human_attributes/viewsets/human_attributes.py changed, reloading.
Performing system checks...

System check identified no issues (0 silenced).
June 03, 2024 - 02:05:57
Django version 4.2.13, using settings 'applegenie.settings'
Starting development server at http://142.93.14.212:8000/
Quit the server with CONTROL-C.

Watching for file changes with StatReloader
/root/applegenie/core_app_root/human_attributes/viewsets/human_attributes.py changed, reloading.
Performing system checks...

System check identified no issues (0 silenced).

You have 1 unapplied migration(s). Your project may not work properly until you apply the migrations for app(s): core_app_root_human_attributes.
Run 'python manage.py migrate' to apply them.
June 03, 2024 - 18:42:51
Django version 4.2.13, using settings 'applegenie.settings'
Starting development server at http://142.93.14.212:8000/
Quit the server with CONTROL-C.

Watching for file changes with StatReloader
Exception in thread django-main-thread:
Traceback (most recent call last):
  File "/usr/lib/python3.12/threading.py", line 1073, in _bootstrap_inner
    self.run()
  File "/usr/lib/python3.12/threading.py", line 1010, in run
    self._target(*self._args, **self._kwargs)
  File "/root/applegenie/venv/lib/python3.12/site-packages/django/utils/autoreload.py", line 64, in wrapper
    fn(*args, **kwargs)
  File "/root/applegenie/venv/lib/python3.12/site-packages/django/core/management/commands/runserver.py", line 133, in inner_run
    self.check(display_num_errors=True)
  File "/root/applegenie/venv/lib/python3.12/site-packages/django/core/management/base.py", line 485, in check
    all_issues = checks.run_checks(
                 ^^^^^^^^^^^^^^^^^^
  File "/root/applegenie/venv/lib/python3.12/site-packages/django/core/checks/registry.py", line 88, in run_checks
    new_errors = check(app_configs=app_configs, databases=databases)
                 ^^^^^^^^^^^^^^^^^^^^^^^^^^^^^^^^^^^^^^^^^^^^^^^^^^^
  File "/root/applegenie/venv/lib/python3.12/site-packages/django/core/checks/urls.py", line 14, in check_url_config
    return check_resolver(resolver)
           ^^^^^^^^^^^^^^^^^^^^^^^^
  File "/root/applegenie/venv/lib/python3.12/site-packages/django/core/checks/urls.py", line 24, in check_resolver
    return check_method()
           ^^^^^^^^^^^^^^
  File "/root/applegenie/venv/lib/python3.12/site-packages/django/urls/resolvers.py", line 494, in check
    for pattern in self.url_patterns:
                   ^^^^^^^^^^^^^^^^^
  File "/root/applegenie/venv/lib/python3.12/site-packages/django/utils/functional.py", line 57, in __get__
    res = instance.__dict__[self.name] = self.func(instance)
                                         ^^^^^^^^^^^^^^^^^^^
  File "/root/applegenie/venv/lib/python3.12/site-packages/django/urls/resolvers.py", line 715, in url_patterns
    patterns = getattr(self.urlconf_module, "urlpatterns", self.urlconf_module)
                       ^^^^^^^^^^^^^^^^^^^
  File "/root/applegenie/venv/lib/python3.12/site-packages/django/utils/functional.py", line 57, in __get__
    res = instance.__dict__[self.name] = self.func(instance)
                                         ^^^^^^^^^^^^^^^^^^^
  File "/root/applegenie/venv/lib/python3.12/site-packages/django/urls/resolvers.py", line 708, in urlconf_module
    return import_module(self.urlconf_name)
           ^^^^^^^^^^^^^^^^^^^^^^^^^^^^^^^^
  File "/usr/lib/python3.12/importlib/__init__.py", line 90, in import_module
    return _bootstrap._gcd_import(name[level:], package, level)
           ^^^^^^^^^^^^^^^^^^^^^^^^^^^^^^^^^^^^^^^^^^^^^^^^^^^^
  File "<frozen importlib._bootstrap>", line 1387, in _gcd_import
  File "<frozen importlib._bootstrap>", line 1360, in _find_and_load
  File "<frozen importlib._bootstrap>", line 1331, in _find_and_load_unlocked
  File "<frozen importlib._bootstrap>", line 935, in _load_unlocked
  File "<frozen importlib._bootstrap_external>", line 995, in exec_module
  File "<frozen importlib._bootstrap>", line 488, in _call_with_frames_removed
  File "/root/applegenie/applegenie/urls.py", line 44, in <module>
    path('',include(('core_app_root.human_attributes.routers','core_app_root.human_attributes'))),
            ^^^^^^^^^^^^^^^^^^^^^^^^^^^^^^^^^^^^^^^^^^^^^^^^^^^^^^^^^^^^^^^^^^^^^^^^^^^^^^^^^^^^
  File "/root/applegenie/venv/lib/python3.12/site-packages/django/urls/conf.py", line 38, in include
    urlconf_module = import_module(urlconf_module)
                     ^^^^^^^^^^^^^^^^^^^^^^^^^^^^^
  File "/usr/lib/python3.12/importlib/__init__.py", line 90, in import_module
    return _bootstrap._gcd_import(name[level:], package, level)
           ^^^^^^^^^^^^^^^^^^^^^^^^^^^^^^^^^^^^^^^^^^^^^^^^^^^^
  File "<frozen importlib._bootstrap>", line 1387, in _gcd_import
  File "<frozen importlib._bootstrap>", line 1360, in _find_and_load
  File "<frozen importlib._bootstrap>", line 1331, in _find_and_load_unlocked
  File "<frozen importlib._bootstrap>", line 935, in _load_unlocked
  File "<frozen importlib._bootstrap_external>", line 995, in exec_module
  File "<frozen importlib._bootstrap>", line 488, in _call_with_frames_removed
  File "/root/applegenie/core_app_root/human_attributes/routers.py", line 2, in <module>
    from core_app_root.human_attributes.viewsets import human_attributes
  File "/root/applegenie/core_app_root/human_attributes/viewsets/human_attributes.py", line 7
    from rest
             ^
SyntaxError: invalid syntax
/root/applegenie/core_app_root/human_attributes/viewsets/human_attributes.py changed, reloading.
Performing system checks...

Watching for file changes with StatReloader
